Workbook

Sheet TOTAL
A3: STT | B3: Phân loại | C3: Tên thiết bị | G3: Số lượng
D4: Mã thiết bị | E4: Cấu hình thiết bị | F4: Hãng sản xuất | G4: Đầu vào | H4: Thực tế | I4: Chênh lệch
A5: 1 | B5: Camera | C5: Đầu lưu trữ hình ảnh | D5: DS-7732NI-K4 | G5: 1 | H5: ='Tầng 1'!AW5+'Tầng 2'!AN5+'Tầng 3'!AW5+'Tầng 4'!AQ5+'Tầng 5'!AL5+'Tầng 6'!V5 -> 1 | I5: =H5-G5 -> 0
A6: 2 | B6: Camera | C6: Ổ cứng Seagate Skyhawk ST4000VX007 | G6: 1 | H6: ='Tầng 1'!AW6+'Tầng 2'!AN6+'Tầng 3'!AW6+'Tầng 4'!AQ6+'Tầng 5'!AL6+'Tầng 6'!V6 -> 1 | I6: =H6-G6 -> 0
A7: 3 | B7: Camera | C7: Camera IP Dome hồng ngoại 2.0 Megapixel | D7: DS-2CD1123G0E-I(L) | G7: 45 | H7: ='Tầng 1'!AW7+'Tầng 2'!AN7+'Tầng 3'!AW7+'Tầng 4'!AQ7+'Tầng 5'!AL7+'Tầng 6'!V7 -> 45 | I7: =H7-G7 -> 0
A8: 4 | B8: Camera | C8: Camera IP dome hồng ngoại trong nhà POE (Hành lang, lớp học,thang máy…) | D8: MS-C2975-PB | G8: 153 | H8: ='Tầng 1'!AW8+'Tầng 2'!AN8+'Tầng 3'!AW8+'Tầng 4'!AQ8+'Tầng 5'!AL8+'Tầng 6'!V8 -> 153 | I8: =H8-G8 -> 0
A9: 5 | B9: Camera | C9: Camera hồng ngoại IP bullet 1080p IP66 (Sân chơi, bể bơi, sân bóng rổ, sân khấu…) | D9: MS-C2962-FPB | G9: 22 | H9: ='Tầng 1'!AW9+'Tầng 2'!AN9+'Tầng 3'!AW9+'Tầng 4'!AQ9+'Tầng 5'!AL9+'Tầng 6'!V9 -> 22 | I9: =H9-G9 -> 0
A10: 6 | B10: Camera | C10: Camera bullet cho ứng dụng nhận diện khuôn mặt với P -Iris (Cổng ra vào 1,2) | D10: MS-C2862-FPB | G10: 2 | H10: ='Tầng 1'!AW10+'Tầng 2'!AN10+'Tầng 3'!AW10+'Tầng 4'!AQ10+'Tầng 5'!AL10+'Tầng 6'!V10 -> 2 | I10: =H10-G10 -> 0
A11: 7 | B11: Camera | C11: Camera IP quay quét (PTZ) -quan sát toàn cảnh | D11: MS-C2941-X30R(P)B | G11: 6 | H11: ='Tầng 1'!AW11+'Tầng 2'!AN11+'Tầng 3'!AW11+'Tầng 4'!AQ11+'Tầng 5'!AL11+'Tầng 6'!V11 -> 6 | I11: =H11-G11 -> 0
A12: 8 | B12: Camera | C12: Đầu lưu trữ hình ảnh | D12: MS-N8032-UH | G12: 7 | H12: ='Tầng 1'!AW12+'Tầng 2'!AN12+'Tầng 3'!AW12+'Tầng 4'!AQ12+'Tầng 5'!AL12+'Tầng 6'!V12 -> 7 | I12: =H12-G12 -> 0
A13: 9 | B13: Camera | C13: Switch 08 cổng PoE + 2 SFP | D13: GS-4210-8P2S | G13: 7 | H13: ='Tầng 1'!AW13+'Tầng 2'!AN13+'Tầng 3'!AW13+'Tầng 4'!AQ13+'Tầng 5'!AL13+'Tầng 6'!V13 -> 6 | I13: =H13-G13 -> -1
A14: 10 | B14: Camera | C14: Switch 24 cổng LAN trung tâm | D14: GS-5220-20T4C4X | G14: 1 | H14: ='Tầng 1'!AW14+'Tầng 2'!AN14+'Tầng 3'!AW14+'Tầng 4'!AQ14+'Tầng 5'!AL14+'Tầng 6'!V14 -> 1 | I14: =H14-G14 -> 0
A15: 11 | B15: Camera | C15: Module quang | D15: MGB series MGB-LX | G15: 5 | H15: ='Tầng 1'!AW15+'Tầng 2'!AN15+'Tầng 3'!AW15+'Tầng 4'!AQ15+'Tầng 5'!AL15+'Tầng 6'!V15 -> 5 | I15: =H15-G15 -> 0
A16: 12 | B16: Camera | C16: Bộ chuyển đổi quang điện | D16: GT-802S | G16: 5 | H16: ='Tầng 1'!AW16+'Tầng 2'!AN16+'Tầng 3'!AW16+'Tầng 4'!AQ16+'Tầng 5'!AL16+'Tầng 6'!V16 -> 5 | I16: =H16-G16 -> 0
A17: 13 | B17: Camera | C17: Bộ chuyển đổi (Dùng cho Camera lắp trong thang máy). | D17: VC-201A-EU | G17: 4 | H17: ='Tầng 1'!AW17+'Tầng 2'!AN17+'Tầng 3'!AW17+'Tầng 4'!AQ17+'Tầng 5'!AL17+'Tầng 6'!V17 -> 4 | I17: =H17-G17 -> 0
A18: 14 | B18: Camera | C18: Bộ thiết bị mạng kéo dài nguồn tích hợp công nghệ POE | D18: FPI -100GA | G18: 2 | H18: ='Tầng 1'!AW18+'Tầng 2'!AN18+'Tầng 3'!AW18+'Tầng 4'!AQ18+'Tầng 5'!AL18+'Tầng 6'!V18 -> 2 | I18: =H18-G18 -> 0
A19: 15 | B19: Camera | C19: Ổ cứng Seagate Skyhawk ST4000VX007 | G19: 28 | H19: ='Tầng 1'!AW19+'Tầng 2'!AN19+'Tầng 3'!AW19+'Tầng 4'!AQ19+'Tầng 5'!AL19+'Tầng 6'!V19 -> 28 | I19: =H19-G19 -> 0
A20: 16 | B20: Camera | C20: Smart Tivi Samsung 49 inch Full HD | D20: 49J5250 | G20: 7 | H20: ='Tầng 1'!AW20+'Tầng 2'!AN20+'Tầng 3'!AW20+'Tầng 4'!AQ20+'Tầng 5'!AL20+'Tầng 6'!V20 -> 7 | I20: =H20-G20 -> 0
A21: 17 | B21: Camera | C21: Dây HDMI 5m | D21: Ugreen | G21: 6 | H21: ='Tầng 1'!AW21+'Tầng 2'!AN21+'Tầng 3'!AW21+'Tầng 4'!AQ21+'Tầng 5'!AL21+'Tầng 6'!V21 -> 6 | I21: =H21-G21 -> 0
A22: 18 | B22: Camera | C22: Máy chủ HP | D22: 4FU52AV HP Z2 Tower G4 | G22: 1 | H22: ='Tầng 1'!AW22+'Tầng 2'!AN22+'Tầng 3'!AW22+'Tầng 4'!AQ22+'Tầng 5'!AL22+'Tầng 6'!V22 -> 1 | I22: =H22-G22 -> 0
A23: 19 | B23: Camera | C23: Màn hình máy tính HP | D23: 3AL28AA HP | G23: 1 | H23: ='Tầng 1'!AW23+'Tầng 2'!AN23+'Tầng 3'!AW23+'Tầng 4'!AQ23+'Tầng 5'!AL23+'Tầng 6'!V23 -> 1 | I23: =H23-G23 -> 0
A24: 20 | B24: Camera | C24: Bộ lưu điện APC Smart-UPS On-Line, 6000 Watts /6000 VA | D24: SRT6KXLI | G24: 1 | H24: ='Tầng 1'!AW24+'Tầng 2'!AN24+'Tầng 3'!AW24+'Tầng 4'!AQ24+'Tầng 5'!AL24+'Tầng 6'!V24 -> 1 | I24: =H24-G24 -> 0
A25: 21 | B25: Camera | C25: Cần điều khiển chuyên dụng cho các loại Camera Bullet, Dome, PTZ ở góc view xa | D25: MS-K02 | G25: 1 | H25: ='Tầng 1'!AW25+'Tầng 2'!AN25+'Tầng 3'!AW25+'Tầng 4'!AQ25+'Tầng 5'!AL25+'Tầng 6'!V25 -> 1 | I25: =H25-G25 -> 0
A26: 22 | B26: Camera | C26: Tủ trung tâm đựng thiết bị 27U -kèm SPU -Cánh cửa lưới - màu đen | D26: VN-/- | G26: 1 | H26: ='Tầng 1'!AW26+'Tầng 2'!AN26+'Tầng 3'!AW26+'Tầng 4'!AQ26+'Tầng 5'!AL26+'Tầng 6'!V26 -> 1 | I26: =H26-G26 -> 0
A27: 23 | B27: Âm thanh | C27: ÂM ly 60w | D27: PLE-1MA060-EU | G27: 48 | H27: ='Tầng 1'!AW27+'Tầng 2'!AN27+'Tầng 3'!AW27+'Tầng 4'!AQ27+'Tầng 5'!AL27+'Tầng 6'!V27 -> 48 | I27: =H27-G27 -> 0
A28: 24 | B28: Âm thanh | C28: ÂM ly 240w | D28: PLE-1ME240-EU | G28: 3 | H28: ='Tầng 1'!AW28+'Tầng 2'!AN28+'Tầng 3'!AW28+'Tầng 4'!AQ28+'Tầng 5'!AL28+'Tầng 6'!V28 -> 3 | I28: =H28-G28 -> 0
A29: 25 | B29: Âm thanh | C29: ÂM ly 120w | D29: PLE-1MA120-EU | G29: 4 | H29: ='Tầng 1'!AW29+'Tầng 2'!AN29+'Tầng 3'!AW29+'Tầng 4'!AQ29+'Tầng 5'!AL29+'Tầng 6'!V29 -> 4 | I29: =H29-G29 -> 0
A30: 26 | B30: Âm thanh | C30: Loa 6w | D30: LHM0606/10 | G30: 144 | H30: ='Tầng 1'!AW30+'Tầng 2'!AN30+'Tầng 3'!AW30+'Tầng 4'!AQ30+'Tầng 5'!AL30+'Tầng 6'!V30 -> 144 | I30: =H30-G30 -> 0
A31: 27 | B31: Âm thanh | C31: Loa 24w | D31: LBC3099/41 | G31: 149 | H31: ='Tầng 1'!AW31+'Tầng 2'!AN31+'Tầng 3'!AW31+'Tầng 4'!AQ31+'Tầng 5'!AL31+'Tầng 6'!V31 -> 146 | I31: =H31-G31 -> -3
... A51: 47 | B51: Âm thanh | C51: Micro chọn 10 vùng IP | D51: IP-100RM | G51: 3 | H51: ='Tầng 1'!AW51+'Tầng 2'!AN51+'Tầng 3'!AW51+'Tầng 4'!AQ51+'Tầng 5'!AL51+'Tầng 6'!V51 -> 3 | I51: =H51-G51 -> 0
A52: 48 | B52: Âm thanh | C52: Tủ 12 U có khay để mixer | G52: 3 | H52: ='Tầng 1'!AW52+'Tầng 2'!AN52+'Tầng 3'!AW52+'Tầng 4'!AQ52+'Tầng 5'!AL52+'Tầng 6'!V52 -> 3 | I52: =H52-G52 -> 0
A53: 49 | B53: Âm thanh | C53: Tủ 32U | D53: D600 | G53: 1 | H53: ='Tầng 1'!AW53+'Tầng 2'!AN53+'Tầng 3'!AW53+'Tầng 4'!AQ53+'Tầng 5'!AL53+'Tầng 6'!V53 -> 1 | I53: =H53-G53 -> 0
A54: 50 | B54: Máy tính bàn | C54: Máy tính bàn DELL | D54: Dell 3470ST | E54: Hệ điều hành: Free Dos CPU: Intel Pentium Gold G5400 3.70 GHz, 4MB RAM: 1x4GB DDR4 Ổ đĩa cứng: 1TB 7200 rpm VGA: Intel HD Graphics Wifi: Có tích hợp wifi,DVD | F54: DELL | G54: 34 | H54: ='Tầng 1'!AW54+'Tầng 2'!AN54+'Tầng 3'!AW54+'Tầng 4'!AQ54+'Tầng 5'!AL54+'Tầng 6'!V54 -> 34 | I54: =H54-G54 -> 0
A55: 51 | B55: Máy tính bàn | C55: Máy tính bàn DELL | D55: Dell 3470ST | E55: Hệ điều hành: Free Dos CPU: Intel Pentium Gold G5400 3.70 GHz, 4MB RAM: 2x4GB DDR4 VGA: Intel HD Graphics Wifi: Có tích hợp wifi,DVD | F55: DELL | G55: 24 | H55: ='Tầng 1'!AW55+'Tầng 2'!AN55+'Tầng 3'!AW55+'Tầng 4'!AQ55+'Tầng 5'!AL55+'Tầng 6'!V55 -> 24 | I55: =H55-G55 -> 0
A56: 52 | B56: Máy tính bàn | C56: Máy tính bàn DELL | D56: Dell 3470ST | E56: Hệ điều hành: Free Dos CPU: Intel Pentium Gold G5400 3.70 GHz, 4MB RAM: 2x4GB DDR4 Ổ đĩa cứng: 1TB 7200 rpm VGA: Intel HD Graphics Wifi: Có tích hợp wifi,DVD | F56: DELL | G56: 2 | H56: ='Tầng 1'!AW56+'Tầng 2'!AN56+'Tầng 3'!AW56+'Tầng 4'!AQ56+'Tầng 5'!AL56+'Tầng 6'!V56 -> 2 | I56: =H56-G56 -> 0
A57: 53 | B57: Màn hình máy tính | C57: Màn hình máy tính để bàn Dell | D57: Man hinh LCD Dell E2016HV 19.5" | E57: 19.5" TN, HD+ 1600x900, WLed Backlight, độ tương phản 600:1, độ sáng: 200 cd/m2, độ trễ: 5ms, kếtt nối: 1 x VGA. | F57: DELL | G57: 58 | H57: ='Tầng 1'!AW57+'Tầng 2'!AN57+'Tầng 3'!AW57+'Tầng 4'!AQ57+'Tầng 5'!AL57+'Tầng 6'!V57 -> 58 | I57: =H57-G57 -> 0
A58: 54 | B58: Màn hình máy tính | C58: Màn hình máy tính để bàn Dell | D58: Màn hình máy tính Dell SE2417HG | E58: 23.6" IPS, Full HD 1920x1080, Led Backlight, độ tương phản 1000:1, độ sáng: 3000 cd/m2, độ trễ: 5ms, kết nối: 1 x HDMI, 1 x VGA. | F58: DELL | G58: 4 | H58: ='Tầng 1'!AW58+'Tầng 2'!AN58+'Tầng 3'!AW58+'Tầng 4'!AQ58+'Tầng 5'!AL58+'Tầng 6'!V58 -> 4 | I58: =H58-G58 -> 0
A59: 55 | B59: Máy tính bàn | C59: Máy tính bàn DELL | D59: Dell 3671 | E59: Máy tính để bàn Dell Vostro 3671 - MT71 G5420W-4G-1T: Intel Pentium G5420 (4MB Cache, up to 3.8GHz); 4GB (lx 4GB) 2400MHz DDR4; 1TB 7200RPM Hard Drive; 6 cling SSD 120GB; DVDRW; Intelgrated Graphics; Chuột; Bàn phím; Windows 10 home | F59: DELL | G59: 14 | H59: ='Tầng 1'!AW59+'Tầng 2'!AN59+'Tầng 3'!AW59+'Tầng 4'!AQ59+'Tầng 5'!AL59+'Tầng 6'!V59 -> 14 | I59: =H59-G59 -> 0
A60: 56 | B60: Màn hình máy tính | C60: Màn hình máy tính để bàn Dell | D60: Dell E2016HV | E60: Man hinh may tinh DELL LCD E2016Hv - 19.5" | F60: Dell | G60: 14 | H60: ='Tầng 1'!AW60+'Tầng 2'!AN60+'Tầng 3'!AW60+'Tầng 4'!AQ60+'Tầng 5'!AL60+'Tầng 6'!V60 -> 14 | I60: =H60-G60 -> 0
A61: 57 | B61: Máy tính bàn | C61: Máy tính bàn | E61: Cpu E5 2689 2.6Ghz*2/TN CM T400i*2/ Main SPM X9DRL/ RAM 16G*4/HĐ 1TB/ASUS RX570 4Gb /K/M/ Case + Nguồn 600W CM/ LCD E2417H | F61: Cây lắp ráp ĐNA | G61: 1 | H61: ='Tầng 1'!AW61+'Tầng 2'!AN61+'Tầng 3'!AW61+'Tầng 4'!AQ61+'Tầng 5'!AL61+'Tầng 6'!V61 -> 1 | I61: =H61-G61 -> 0
...

Sheet Tầng 1
A3: STT | B3: Phân loại | C3: Tên thiết bị | G3: Vị trí lắp đặt - Người sử dụng (Số lượng) | AW3: Tổng
D4: Mã thiết bị | E4: Cấu hình thiết bị | F4: Hãng sản xuất | G4: 1F1 | H4: 1F2 (Bảo vệ) | I4: 1F3 | J4: 1F4 | K4: 1F5 | L4: 1F6 | M4: 1F7 | N4: 1F8 | O4: 1F9 | P4: 1F10 | Q4: 1F11 | R4: 1F12 | S4: 1F13 | T4: 1F14 | U4: 1F15 | V4: 1F16 | W4: 1F17 | X4: 1F18 | Y4: 1F19 | Z4: 1F20 (Hành lang khu mầm non) | AA4: 1F21 | AB4: WC Y4-Y5 | AC4: CT bộ Y4-Y5 | AD4: HL Y4-Y12 | AE4: Sảnh Y7-Y9 | AF4: WC nhà ăn | AG4: QL bếp ăn | AH4: HL X1-X9 | AI4: Sân bóng rổ | AJ4: Sân bóng đá | AK4: Bể bơi | AL4: Sảnh thang máy | AM4: Thang bộ Y13-Y14 | AN4: Sảnh bảo vệ | AO4: Sân Y4-Y13 | AP4: Cổng số 1 | AQ4: Cổng số 2 | AR4: Lái xe 1 | AS4: Lái xe 2 | AT4: Trạm Bơm | AU4: Lao công | AV4: Hàng rào quanh trường
A5: 1 | B5: Camera | C5: Đầu lưu trữ hình ảnh | D5: DS-7732NI-K4 | AW5: =SUM(G5:AV5) -> 0
A6: 2 | B6: Camera | C6: Ổ cứng Seagate Skyhawk ST4000VX007 | AW6: =SUM(G6:AV6) -> 0
A7: 3 | B7: Camera | C7: Camera IP Dome hồng ngoại 2.0 Megapixel | D7: DS-2CD1123G0E-I(L) | I7: 1 | AC7: 1 | AM7: 1 | AW7: =SUM(G7:AV7) -> 3
A8: 4 | B8: Camera | C8: Camera IP dome hồng ngoại trong nhà POE (Hành lang, lớp học,thang máy…) | D8: MS-C2975-PB | G8: 1 | H8: 1 | I8: 9 | J8: 1 | K8: 1 | L8: 1 | O8: 1 | P8: 1 | Q8: 1 | S8: 1 | T8: 1 | U8: 1 | V8: 1 | W8: 1 | X8: 1 | Y8: 1 | Z8: 5 | AD8: 7 | AH8: 3 | AL8: 1 | AW8: =SUM(G8:AV8) -> 40
A9: 5 | B9: Camera | C9: Camera hồng ngoại IP bullet 1080p IP66 (Sân chơi, bể bơi, sân bóng rổ, sân khấu…) | D9: MS-C2962-FPB | AI9: 2 | AK9: 2 | AO9: 5 | AV9: 9 | AW9: =SUM(G9:AV9) -> 18
A10: 6 | B10: Camera | C10: Camera bullet cho ứng dụng nhận diện khuôn mặt với P -Iris (Cổng ra vào 1,2) | D10: MS-C2862-FPB | AP10: 1 | AQ10: 1 | AW10: =SUM(G10:AV10) -> 2
A11: 7 | B11: Camera | C11: Camera IP quay quét (PTZ) -quan sát toàn cảnh | D11: MS-C2941-X30R(P)B | AJ11: 1 | AN11: 1 | AQ11: 1 | AW11: =SUM(G11:AV11) -> 3
A12: 8 | B12: Camera | C12: Đầu lưu trữ hình ảnh | D12: MS-N8032-UH | AW12: =SUM(G12:AV12) -> 0
A13: 9 | B13: Camera | C13: Switch 08 cổng PoE + 2 SFP | D13: GS-4210-8P2S | H13: 1 | AR13: 1 | AT13: 1 | AU13: 1 | AW13: =SUM(G13:AV13) -> 4
A14: 10 | B14: Camera | C14: Switch 24 cổng LAN trung tâm | D14: GS-5220-20T4C4X | AW14: =SUM(G14:AV14) -> 0
A15: 11 | B15: Camera | C15: Module quang | D15: MGB series MGB-LX | AU15: 1 | AW15: =SUM(G15:AV15) -> 1
A16: 12 | B16: Camera | C16: Bộ chuyển đổi quang điện | D16: GT-802S | AW16: =SUM(G16:AV16) -> 0
A17: 13 | B17: Camera | C17: Bộ chuyển đổi (Dùng cho Camera lắp trong thang máy). | D17: VC-201A-EU | AW17: =SUM(G17:AV17) -> 0
A18: 14 | B18: Camera | C18: Bộ thiết bị mạng kéo dài nguồn tích hợp công nghệ POE | D18: FPI -100GA | AW18: =SUM(G18:AV18) -> 0
A19: 15 | B19: Camera | C19: Ổ cứng Seagate Skyhawk ST4000VX007 | AW19: =SUM(G19:AV19) -> 0
A20: 16 | B20: Camera | C20: Smart Tivi Samsung 49 inch Full HD | D20: 49J5250 | H20: 3 | AQ20: 1 | AW20: =SUM(G20:AV20) -> 4
A21: 17 | B21: Camera | C21: Dây HDMI 5m | D21: Ugreen | H21: 3 | AW21: =SUM(G21:AV21) -> 3
A22: 18 | B22: Camera | C22: Máy chủ HP | D22: 4FU52AV HP Z2 Tower G4 | H22: 1 | AW22: =SUM(G22:AV22) -> 1
A23: 19 | B23: Camera | C23: Màn hình máy tính HP | D23: 3AL28AA HP | AW23: =SUM(G23:AV23) -> 0
A24: 20 | B24: Camera | C24: Bộ lưu điện APC Smart-UPS On-Line, 6000 Watts /6000 VA | D24: SRT6KXLI | AW24: =SUM(G24:AV24) -> 0
A25: 21 | B25: Camera | C25: Cần điều khiển chuyên dụng cho các loại Camera Bullet, Dome, PTZ ở góc view xa | D25: MS-K02 | H25: 1 | AW25: =SUM(G25:AV25) -> 1
A26: 22 | B26: Camera | C26: Tủ trung tâm đựng thiết bị 27U -kèm SPU -Cánh cửa lưới - màu đen | D26: VN-/- | AW26: =SUM(G26:AV26) -> 0
A27: 23 | B27: Âm thanh | C27: ÂM ly 60w | D27: PLE-1MA060-EU | N27: 1 | T27: 1 | U27: 1 | V27: 1 | AW27: =SUM(G27:AV27) -> 4
A28: 24 | B28: Âm thanh | C28: ÂM ly 240w | D28: PLE-1ME240-EU | M28: 1 | AW28: =SUM(G28:AV28) -> 1
A29: 25 | B29: Âm thanh | C29: ÂM ly 120w | D29: PLE-1MA120-EU | AS29: 1 | AW29: =SUM(G29:AV29) -> 1
A30: 26 | B30: Âm thanh | C30: Loa 6w | D30: LHM0606/10 | Z30: 6 | AB30: 2 | AD30: 10 | AE30: 2 | AF30: 1 | AH30: 6 | AW30: =SUM(G30:AV30) -> 27
A31: 27 | B31: Âm thanh | C31: Loa 24w | D31: LBC3099/41 | I31: 6 | M31: 6 | N31: 4 | T31: 2 | U31: 2 | V31: 2 | W31: 2 | X31: 2 | Y31: 2 | AN31: 4 | AW31: =SUM(G31:AV31) -> 32
A32: 28 | B32: Âm thanh | C32: Mic không dây | D32: MW1-HTX-F5 | M32: 2 | AS32: 1 | AW32: =SUM(G32:AV32) -> 3
A33: 29 | B33: Âm thanh | C33: ÂM ly 480w | D33: LBB1938/20 | G33: 1 | AW33: =SUM(G33:AV33) -> 1
A34: 30 | B34: Âm thanh | C34: Bộ thu | D34: MW1-RX-F5 | M34: 1 | U34: 1 | V34: 1 | W34: 1 | AS34: 1 | AW34: =SUM(G34:AV34) -> 5
A35: 31 | B35: Âm thanh | C35: ÂM ly 480w | D35: FV-248PA | AW35: =SUM(G35:AV35) -> 0
A36: 32 | B36: Âm thanh | C36: Bàn trộn (Mixer) | D36: MG10XU | AS36: 1 | AW36: =SUM(G36:AV36) -> 1
A37: 33 | B37: Âm thanh | C37: Mic đại biểu | D37: CCS-DL | M37: 25 | AW37: =SUM(G37:AV37) -> 25
A38: 34 | B38: Âm thanh | C38: Mic chủ tịch | D38: CCS-CML | M38: 1 | AW38: =SUM(G38:AV38) -> 1
A39: 35 | B39: Âm thanh | C39: Bộ điều khiển trung tâm | D39: CCS-CUD | M39: 1 | AW39: =SUM(G39:AV39) -> 1
A40: 36 | B40: Âm thanh | C40: cáp nối dài 10M | D40: LBB3316/10 | M40: 2 | AW40: =SUM(G40:AV40) -> 2
A41: 37 | B41: Âm thanh | C41: Loa hộp 30w | D41: LB2/UC30-D1 | AW41: =SUM(G41:AV41) -> 0
A42: 38 | B42: Âm thanh | C42: Mic cài ve | D42: MW1-LTX-F5 | AW42: =SUM(G42:AV42) -> 0
...

Sheet Tầng 2
A3: STT | B3: Phân loại | C3: Tên thiết bị | G3: Vị trí lắp đặt - Người sử dụng (Số lượng) | AN3: Tổng
D4: Mã thiết bị | E4: Cấu hình thiết bị | F4: Hãng sản xuất | G4: 2F1 | H4: 2F2 | I4: 2F3 | J4: 2F4 | K4: 2F5 | L4: 2F6 | M4: 2F7 | N4: 2F8 | O4: 2F9 | P4: 2F10 | Q4: 2F11 | R4: 2F12 | S4: 2F13 | T4: 2F14 | U4: 2F15 | V4: 2F16 | W4: 2F17 | X4: 2F18 | Y4: 2F19 | Z4: 2F20 | AA4: 2F21 | AB4: 2F22 | AC4: 2F23 | AD4: WC Y4-Y5 | AE4: WC Y15-Y16 | AF4: CT bộ Y4-Y5 | AG4: HL Y1-Y16 | AH4: Sảnh Y7-Y9 | AI4: WC Y10-Y11 | AJ4: HL X1-X7 | AK4: HL thư viện | AL4: Sảnh thang máy | AM4: Thang bộ Y13-Y14
B5: Camera | C5: Đầu lưu trữ hình ảnh | D5: DS-7732NI-K4 | AN5: =SUM(G5:AM5) -> 0
B6: Camera | C6: Ổ cứng Seagate Skyhawk ST4000VX007 | AN6: =SUM(G6:AM6) -> 0
B7: Camera | C7: Camera IP Dome hồng ngoại 2.0 Megapixel | D7: DS-2CD1123G0E-I(L) | AF7: 1 | AN7: =SUM(G7:AM7) -> 1
A8: 1 | B8: Camera | C8: Camera IP dome hồng ngoại trong nhà POE (Hành lang, lớp học,thang máy…) | D8: MS-C2975-PB | H8: 1 | J8: 1 | K8: 7 | L8: 1 | M8: 1 | N8: 2 | O8: 1 | P8: 1 | Q8: 1 | R8: 1 | S8: 1 | T8: 1 | U8: 1 | V8: 1 | W8: 1 | X8: 1 | Y8: 1 | Z8: 1 | AA8: 1 | AB8: 1 | AC8: 3 | AG8: 11 | AJ8: 3 | AK8: 1 | AL8: 1 | AN8: =SUM(G8:AM8) -> 46
A9: 2 | B9: Camera | C9: Camera hồng ngoại IP bullet 1080p IP66 (Sân chơi, bể bơi, sân bóng rổ, sân khấu…) | D9: MS-C2962-FPB | AN9: =SUM(G9:AM9) -> 0
A10: 3 | B10: Camera | C10: Camera bullet cho ứng dụng nhận diện khuôn mặt với P -Iris (Cổng ra vào 1,2) | D10: MS-C2862-FPB | AN10: =SUM(G10:AM10) -> 0
A11: 4 | B11: Camera | C11: Camera IP quay quét (PTZ) -quan sát toàn cảnh | D11: MS-C2941-X30R(P)B | AN11: =SUM(G11:AM11) -> 0
A12: 5 | B12: Camera | C12: Đầu lưu trữ hình ảnh | D12: MS-N8032-UH | AN12: =SUM(G12:AM12) -> 0
A13: 6 | B13: Camera | C13: Switch 08 cổng PoE + 2 SFP | D13: GS-4210-8P2S | AN13: =SUM(G13:AM13) -> 0
A14: 7 | B14: Camera | C14: Switch 24 cổng LAN trung tâm | D14: GS-5220-20T4C4X | AN14: =SUM(G14:AM14) -> 0
A15: 8 | B15: Camera | C15: Module quang | D15: MGB series MGB-LX | AN15: =SUM(G15:AM15) -> 0
A16: 9 | B16: Camera | C16: Bộ chuyển đổi quang điện | D16: GT-802S | AN16: =SUM(G16:AM16) -> 0
A17: 10 | B17: Camera | C17: Bộ chuyển đổi (Dùng cho Camera lắp trong thang máy). | D17: VC-201A-EU | AN17: =SUM(G17:AM17) -> 0
A18: 11 | B18: Camera | C18: Bộ thiết bị mạng kéo dài nguồn tích hợp công nghệ POE | D18: FPI -100GA | AN18: =SUM(G18:AM18) -> 0
A19: 12 | B19: Camera | C19: Ổ cứng Seagate Skyhawk ST4000VX007 | AN19: =SUM(G19:AM19) -> 0
A20: 13 | B20: Camera | C20: Smart Tivi Samsung 49 inch Full HD | D20: 49J5250 | AN20: =SUM(G20:AM20) -> 0
A21: 14 | B21: Camera | C21: Dây HDMI 5m | D21: Ugreen | AN21: =SUM(G21:AM21) -> 0
A22: 15 | B22: Camera | C22: Máy chủ HP | D22: 4FU52AV HP Z2 Tower G4 | AN22: =SUM(G22:AM22) -> 0
A23: 16 | B23: Camera | C23: Màn hình máy tính HP | D23: 3AL28AA HP | AN23: =SUM(G23:AM23) -> 0
A24: 17 | B24: Camera | C24: Bộ lưu điện APC Smart-UPS On-Line, 6000 Watts /6000 VA | D24: SRT6KXLI | AN24: =SUM(G24:AM24) -> 0
A25: 18 | B25: Camera | C25: Cần điều khiển chuyên dụng cho các loại Camera Bullet, Dome, PTZ ở góc view xa | D25: MS-K02 | AN25: =SUM(G25:AM25) -> 0
A26: 19 | B26: Camera | C26: Tủ trung tâm đựng thiết bị 27U -kèm SPU -Cánh cửa lưới - màu đen | D26: VN-/- | AN26: =SUM(G26:AM26) -> 0
A27: 20 | B27: Âm thanh | C27: ÂM ly 60w | D27: PLE-1MA060-EU | H27: 1 | J27: 1 | L27: 1 | M27: 1 | O27: 1 | P27: 1 | Q27: 1 | R27: 1 | S27: 1 | T27: 1 | U27: 1 | W27: 1 | X27: 1 | Y27: 1 | AB27: 1 | AN27: =SUM(G27:AM27) -> 15
A28: 21 | B28: Âm thanh | C28: ÂM ly 240w | D28: PLE-1ME240-EU | AN28: =SUM(G28:AM28) -> 0
A29: 22 | B29: Âm thanh | C29: ÂM ly 120w | D29: PLE-1MA120-EU | X29: 1 | AN29: =SUM(G29:AM29) -> 1
A30: 23 | B30: Âm thanh | C30: Loa 6w | D30: LHM0606/10 | AD30: 4 | AE30: 2 | AG30: 15 | AH30: 1 | AI30: 4 | AJ30: 5 | AK30: 4 | AN30: =SUM(G30:AM30) -> 35
A31: 24 | B31: Âm thanh | C31: Loa 24w | D31: LBC3099/41 | H31: 2 | J31: 2 | K31: 9 | L31: 2 | M31: 2 | O31: 2 | P31: 2 | Q31: 2 | R31: 2 | S31: 2 | T31: 2 | U31: 2 | W31: 2 | X31: 2 | Y31: 2 | AB31: 2 | AN31: =SUM(G31:AM31) -> 39
A32: 25 | B32: Âm thanh | C32: Mic không dây | D32: MW1-HTX-F5 | AN32: =SUM(G32:AM32) -> 0
A33: 26 | B33: Âm thanh | C33: ÂM ly 480w | D33: LBB1938/20 | AN33: =SUM(G33:AM33) -> 0
A34: 27 | B34: Âm thanh | C34: Bộ thu | D34: MW1-RX-F5 | H34: 1 | J34: 1 | L34: 1 | P34: 1 | R34: 1 | S34: 1 | T34: 1 | U34: 1 | AN34: =SUM(G34:AM34) -> 8
A35: 28 | B35: Âm thanh | C35: ÂM ly 480w | D35: FV-248PA | AN35: =SUM(G35:AM35) -> 0
A36: 29 | B36: Âm thanh | C36: Bàn trộn (Mixer) | D36: MG10XU | AN36: =SUM(G36:AM36) -> 0
A37: 30 | B37: Âm thanh | C37: Mic đại biểu | D37: CCS-DL | AN37: =SUM(G37:AM37) -> 0
A38: 31 | B38: Âm thanh | C38: Mic chủ tịch | D38: CCS-CML | AN38: =SUM(G38:AM38) -> 0
A39: 32 | B39: Âm thanh | C39: Bộ điều khiển trung tâm | D39: CCS-CUD | AN39: =SUM(G39:AM39) -> 0
A40: 33 | B40: Âm thanh | C40: cáp nối dài 10M | D40: LBB3316/10 | AN40: =SUM(G40:AM40) -> 0
A41: 34 | B41: Âm thanh | C41: Loa hộp 30w | D41: LB2/UC30-D1 | X41: 2 | AN41: =SUM(G41:AM41) -> 2
A42: 35 | B42: Âm thanh | C42: Mic cài ve | D42: MW1-LTX-F5 | AN42: =SUM(G42:AM42) -> 0
...

Sheet Tầng 3
A3: STT | B3: Phân loại | C3: Tên thiết bị | G3: Vị trí lắp đặt - Người sử dụng (Số lượng) | AW3: Tổng
D4: Mã thiết bị | E4: Cấu hình thiết bị | F4: Hãng sản xuất | G4: 3F1 | H4: 3F2 | I4: 3F3 | J4: 3F4 | K4: 3F5 | L4: 3F6 | M4: 3F7 | N4: 3F8 | O4: 3F9 | P4: 3F10 | Q4: 3F11 | R4: 3F12 | S4: 3F13 | T4: 3F14 | U4: 3F15 | V4: 3F16 | W4: 3F17 | X4: 3F18 | Y4: 3F19 | Z4: 3F20 | AA4: 3F21 | AB4: 3F22 | AC4: 3F23 | AD4: 3F24 | AE4: 3F25 | AF4: 3F26 | AG4: 3F27 | AH4: 3F28 | AI4: WC Y4-Y5 | AJ4: WC Y15-Y16 | AK4: WC Y11-Y12 | AL4: WC đối diện nhà đa năng | AM4: Kho IT | AN4: CT bộ Y4-Y5 | AO4: HL Y1-Y16 | AP4: Nhà đa năng | AQ4: Sảnh Y7-Y9 | AR4: HL Phòng võ | AS4: HL X1-X7 | AT4: Thang bộ Y9-Y10 | AU4: Sảnh thang máy | AV4: Thang bộ Y13-Y14
A5: 1 | B5: Camera | C5: Đầu lưu trữ hình ảnh | D5: DS-7732NI-K4 | AC5: 1 | AW5: =SUM(G5:AV5) -> 1
A6: 2 | B6: Camera | C6: Ổ cứng Seagate Skyhawk ST4000VX007 | AC6: 1 | AW6: =SUM(G6:AV6) -> 1
A7: 3 | B7: Camera | C7: Camera IP Dome hồng ngoại 2.0 Megapixel | D7: DS-2CD1123G0E-I(L) | I7: 1 | M7: 1 | N7: 1 | O7: 1 | U7: 1 | W7: 1 | AN7: 1 | AW7: =SUM(G7:AV7) -> 7
A8: 4 | B8: Camera | C8: Camera IP dome hồng ngoại trong nhà POE (Hành lang, lớp học,thang máy…) | D8: MS-C2975-PB | H8: 1 | J8: 1 | K8: 1 | L8: 1 | P8: 1 | Q8: 1 | R8: 1 | S8: 1 | Y8: 1 | Z8: 1 | AA8: 1 | AD8: 1 | AE8: 1 | AF8: 1 | AG8: 1 | AM8: 2 | AO8: 10 | AR8: 2 | AS8: 5 | AU8: 1 | AW8: =SUM(G8:AV8) -> 35
A9: 5 | B9: Camera | C9: Camera hồng ngoại IP bullet 1080p IP66 (Sân chơi, bể bơi, sân bóng rổ, sân khấu…) | D9: MS-C2962-FPB | AP9: 2 | AW9: =SUM(G9:AV9) -> 2
A10: 6 | B10: Camera | C10: Camera bullet cho ứng dụng nhận diện khuôn mặt với P -Iris (Cổng ra vào 1,2) | D10: MS-C2862-FPB | AW10: =SUM(G10:AV10) -> 0
A11: 7 | B11: Camera | C11: Camera IP quay quét (PTZ) -quan sát toàn cảnh | D11: MS-C2941-X30R(P)B | AW11: =SUM(G11:AV11) -> 0
A12: 8 | B12: Camera | C12: Đầu lưu trữ hình ảnh | D12: MS-N8032-UH | AC12: 7 | AW12: =SUM(G12:AV12) -> 7
A13: 9 | B13: Camera | C13: Switch 08 cổng PoE + 2 SFP | D13: GS-4210-8P2S | AW13: =SUM(G13:AV13) -> 0
A14: 10 | B14: Camera | C14: Switch 24 cổng LAN trung tâm | D14: GS-5220-20T4C4X | AC14: 1 | AW14: =SUM(G14:AV14) -> 1
A15: 11 | B15: Camera | C15: Module quang | D15: MGB series MGB-LX | AM15: 3 | AW15: =SUM(G15:AV15) -> 3
A16: 12 | B16: Camera | C16: Bộ chuyển đổi quang điện | D16: GT-802S | AM16: 3 | AW16: =SUM(G16:AV16) -> 3
A17: 13 | B17: Camera | C17: Bộ chuyển đổi (Dùng cho Camera lắp trong thang máy). | D17: VC-201A-EU | AW17: =SUM(G17:AV17) -> 0
A18: 14 | B18: Camera | C18: Bộ thiết bị mạng kéo dài nguồn tích hợp công nghệ POE | D18: FPI -100GA | AW18: =SUM(G18:AV18) -> 0
A19: 15 | B19: Camera | C19: Ổ cứng Seagate Skyhawk ST4000VX007 | AC19: 28 | AW19: =SUM(G19:AV19) -> 28
A20: 16 | B20: Camera | C20: Smart Tivi Samsung 49 inch Full HD | D20: 49J5250 | AC20: 2 | AM20: 1 | AW20: =SUM(G20:AV20) -> 3
A21: 17 | B21: Camera | C21: Dây HDMI 5m | D21: Ugreen | AC21: 3 | AW21: =SUM(G21:AV21) -> 3
A22: 18 | B22: Camera | C22: Máy chủ HP | D22: 4FU52AV HP Z2 Tower G4 | AW22: =SUM(G22:AV22) -> 0
A23: 19 | B23: Camera | C23: Màn hình máy tính HP | D23: 3AL28AA HP | AC23: 1 | AW23: =SUM(G23:AV23) -> 1
A24: 20 | B24: Camera | C24: Bộ lưu điện APC Smart-UPS On-Line, 6000 Watts /6000 VA | D24: SRT6KXLI | AC24: 1 | AW24: =SUM(G24:AV24) -> 1
A25: 21 | B25: Camera | C25: Cần điều khiển chuyên dụng cho các loại Camera Bullet, Dome, PTZ ở góc view xa | D25: MS-K02 | AW25: =SUM(G25:AV25) -> 0
A26: 22 | B26: Camera | C26: Tủ trung tâm đựng thiết bị 27U -kèm SPU -Cánh cửa lưới - màu đen | D26: VN-/- | AC26: 1 | AW26: =SUM(G26:AV26) -> 1
A27: 23 | B27: Âm thanh | C27: ÂM ly 60w | D27: PLE-1MA060-EU | H27: 1 | J27: 1 | K27: 1 | L27: 1 | M27: 1 | P27: 1 | Q27: 1 | R27: 1 | V27: 1 | W27: 1 | X27: 1 | Y27: 1 | Z27: 1 | AA27: 1 | AD27: 1 | AG27: 1 | AW27: =SUM(G27:AV27) -> 16
A28: 24 | B28: Âm thanh | C28: ÂM ly 240w | D28: PLE-1ME240-EU | AC28: 1 | AW28: =SUM(G28:AV28) -> 1
A29: 25 | B29: Âm thanh | C29: ÂM ly 120w | D29: PLE-1MA120-EU | AC29: 1 | AM29: 1 | AW29: =SUM(G29:AV29) -> 2
A30: 26 | B30: Âm thanh | C30: Loa 6w | D30: LHM0606/10 | M30: 2 | AI30: 4 | AK30: 4 | AO30: 15 | AQ30: 2 | AS30: 5 | AW30: =SUM(G30:AV30) -> 32
A31: 27 | B31: Âm thanh | C31: Loa 24w | D31: LBC3099/41 | H31: 2 | J31: 2 | K31: 2 | L31: 2 | M31: 1 | P31: 2 | Q31: 2 | R31: 2 | S31: 2 | T31: 2 | U31: 2 | V31: 2 | W31: 2 | X31: 2 | Y31: 2 | Z31: 2 | AA31: 2 | AD31: 2 | AG31: 2 | AW31: =SUM(G31:AV31) -> 37
A32: 28 | B32: Âm thanh | C32: Mic không dây | D32: MW1-HTX-F5 | K32: 1 | M32: 1 | AM32: 5 | AW32: =SUM(G32:AV32) -> 7
A33: 29 | B33: Âm thanh | C33: ÂM ly 480w | D33: LBB1938/20 | AM33: 1 | AP33: 1 | AW33: =SUM(G33:AV33) -> 2
A34: 30 | B34: Âm thanh | C34: Bộ thu | D34: MW1-RX-F5 | K34: 1 | M34: 1 | AM34: 14 | AW34: =SUM(G34:AV34) -> 16
A35: 31 | B35: Âm thanh | C35: ÂM ly 480w | D35: FV-248PA | AC35: 2 | AW35: =SUM(G35:AV35) -> 2
A36: 32 | B36: Âm thanh | C36: Bàn trộn (Mixer) | D36: MG10XU | AW36: =SUM(G36:AV36) -> 0
A37: 33 | B37: Âm thanh | C37: Mic đại biểu | D37: CCS-DL | AM37: 2 | AW37: =SUM(G37:AV37) -> 2
A38: 34 | B38: Âm thanh | C38: Mic chủ tịch | D38: CCS-CML | AW38: =SUM(G38:AV38) -> 0
A39: 35 | B39: Âm thanh | C39: Bộ điều khiển trung tâm | D39: CCS-CUD | AW39: =SUM(G39:AV39) -> 0
A40: 36 | B40: Âm thanh | C40: cáp nối dài 10M | D40: LBB3316/10 | AW40: =SUM(G40:AV40) -> 0
A41: 37 | B41: Âm thanh | C41: Loa hộp 30w | D41: LB2/UC30-D1 | AP41: 2 | AW41: =SUM(G41:AV41) -> 2
A42: 38 | B42: Âm thanh | C42: Mic cài ve | D42: MW1-LTX-F5 | AM42: 19 | AW42: =SUM(G42:AV42) -> 19
...

Sheet Tầng 4
A3: STT | B3: Phân loại | C3: Tên thiết bị | G3: Vị trí lắp đặt - Người sử dụng (Số lượng) | AQ3: Tổng
D4: Mã thiết bị | E4: Cấu hình thiết bị | F4: Hãng sản xuất | G4: 4F1 | H4: 4F2 | I4: 4F3 | J4: 4F4 | K4: 4F5 | L4: 4F6 | M4: 4F7 | N4: 4F8 | O4: 4F9 | P4: 4F10 | Q4: 4F11 | R4: 4F12 | S4: 4F13 | T4: 4F14 | U4: 4F15 | V4: 4F16 | W4: 4F17 | X4: 4F18 | Y4: 4F19 | Z4: 4F20 | AA4: 4F21 | AB4: 4F22 | AC4: 4F23 | AD4: WC Y4-Y5 | AE4: WC Y15-Y16 | AF4: WC Y11-Y12 | AG4: Sân khấu | AH4: WC sân khấu | AI4: CT bộ Y4-Y5 | AJ4: HL Y1-Y16 | AK4: Sảnh cầu thang gỗ | AL4: Sảnh Y7-Y9 | AM4: HL X1-X7 | AN4: Thang bộ Y9-Y10 | AO4: Sảnh thang máy | AP4: Thang bộ Y13-Y14
A5: 1 | B5: Camera | C5: Đầu lưu trữ hình ảnh | D5: DS-7732NI-K4 | AQ5: =SUM(G5:AP5) -> 0
A6: 2 | B6: Camera | C6: Ổ cứng Seagate Skyhawk ST4000VX007 | AQ6: =SUM(G6:AP6) -> 0
A7: 3 | B7: Camera | C7: Camera IP Dome hồng ngoại 2.0 Megapixel | D7: DS-2CD1123G0E-I(L) | M7: 1 | N7: 1 | O7: 1 | Q7: 1 | R7: 1 | S7: 1 | T7: 1 | U7: 1 | V7: 1 | W7: 1 | X7: 1 | Y7: 1 | Z7: 1 | AA7: 1 | AB7: 1 | AI7: 1 | AQ7: =SUM(G7:AP7) -> 16
A8: 4 | B8: Camera | C8: Camera IP dome hồng ngoại trong nhà POE (Hành lang, lớp học,thang máy…) | D8: MS-C2975-PB | H8: 1 | J8: 1 | L8: 1 | AJ8: 10 | AK8: 2 | AM8: 3 | AO8: 1 | AQ8: =SUM(G8:AP8) -> 19
A9: 5 | B9: Camera | C9: Camera hồng ngoại IP bullet 1080p IP66 (Sân chơi, bể bơi, sân bóng rổ, sân khấu…) | D9: MS-C2962-FPB | AG9: 2 | AQ9: =SUM(G9:AP9) -> 2
A10: 6 | B10: Camera | C10: Camera bullet cho ứng dụng nhận diện khuôn mặt với P -Iris (Cổng ra vào 1,2) | D10: MS-C2862-FPB | AQ10: =SUM(G10:AP10) -> 0
A11: 7 | B11: Camera | C11: Camera IP quay quét (PTZ) -quan sát toàn cảnh | D11: MS-C2941-X30R(P)B | AQ11: =SUM(G11:AP11) -> 0
A12: 8 | B12: Camera | C12: Đầu lưu trữ hình ảnh | D12: MS-N8032-UH | AQ12: =SUM(G12:AP12) -> 0
A13: 9 | B13: Camera | C13: Switch 08 cổng PoE + 2 SFP | D13: GS-4210-8P2S | AQ13: =SUM(G13:AP13) -> 0
A14: 10 | B14: Camera | C14: Switch 24 cổng LAN trung tâm | D14: GS-5220-20T4C4X | AQ14: =SUM(G14:AP14) -> 0
A15: 11 | B15: Camera | C15: Module quang | D15: MGB series MGB-LX | AQ15: =SUM(G15:AP15) -> 0
A16: 12 | B16: Camera | C16: Bộ chuyển đổi quang điện | D16: GT-802S | AQ16: =SUM(G16:AP16) -> 0
A17: 13 | B17: Camera | C17: Bộ chuyển đổi (Dùng cho Camera lắp trong thang máy). | D17: VC-201A-EU | AQ17: =SUM(G17:AP17) -> 0
A18: 14 | B18: Camera | C18: Bộ thiết bị mạng kéo dài nguồn tích hợp công nghệ POE | D18: FPI -100GA | AQ18: =SUM(G18:AP18) -> 0
A19: 15 | B19: Camera | C19: Ổ cứng Seagate Skyhawk ST4000VX007 | AQ19: =SUM(G19:AP19) -> 0
A20: 16 | B20: Camera | C20: Smart Tivi Samsung 49 inch Full HD | D20: 49J5250 | AQ20: =SUM(G20:AP20) -> 0
A21: 17 | B21: Camera | C21: Dây HDMI 5m | D21: Ugreen | AQ21: =SUM(G21:AP21) -> 0
A22: 18 | B22: Camera | C22: Máy chủ HP | D22: 4FU52AV HP Z2 Tower G4 | AQ22: =SUM(G22:AP22) -> 0
A23: 19 | B23: Camera | C23: Màn hình máy tính HP | D23: 3AL28AA HP | AQ23: =SUM(G23:AP23) -> 0
A24: 20 | B24: Camera | C24: Bộ lưu điện APC Smart-UPS On-Line, 6000 Watts /6000 VA | D24: SRT6KXLI | AQ24: =SUM(G24:AP24) -> 0
A25: 21 | B25: Camera | C25: Cần điều khiển chuyên dụng cho các loại Camera Bullet, Dome, PTZ ở góc view xa | D25: MS-K02 | AQ25: =SUM(G25:AP25) -> 0
A26: 22 | B26: Camera | C26: Tủ trung tâm đựng thiết bị 27U -kèm SPU -Cánh cửa lưới - màu đen | D26: VN-/- | AQ26: =SUM(G26:AP26) -> 0
A27: 23 | B27: Âm thanh | C27: ÂM ly 60w | D27: PLE-1MA060-EU | H27: 1 | J27: 1 | L27: 1 | P27: 1 | Q27: 1 | R27: 1 | S27: 1 | T27: 1 | U27: 1 | AQ27: =SUM(G27:AP27) -> 9
A28: 24 | B28: Âm thanh | C28: ÂM ly 240w | D28: PLE-1ME240-EU | AQ28: =SUM(G28:AP28) -> 0
A29: 25 | B29: Âm thanh | C29: ÂM ly 120w | D29: PLE-1MA120-EU | AQ29: =SUM(G29:AP29) -> 0
A30: 26 | B30: Âm thanh | C30: Loa 6w | D30: LHM0606/10 | J30: 4 | AD30: 4 | AE30: 1 | AF30: 4 | AJ30: 17 | AK30: 2 | AL30: 2 | AQ30: =SUM(G30:AP30) -> 34
A31: 27 | B31: Âm thanh | C31: Loa 24w | D31: LBC3099/41 | H31: 2 | L31: 2 | O31: 2 | Q31: 2 | R31: 2 | S31: 2 | T31: 2 | U31: 2 | V31: 2 | AQ31: =SUM(G31:AP31) -> 18
A32: 28 | B32: Âm thanh | C32: Mic không dây | D32: MW1-HTX-F5 | AG32: 2 | AQ32: =SUM(G32:AP32) -> 2
A33: 29 | B33: Âm thanh | C33: ÂM ly 480w | D33: LBB1938/20 | AQ33: =SUM(G33:AP33) -> 0
A34: 30 | B34: Âm thanh | C34: Bộ thu | D34: MW1-RX-F5 | AG34: 12 | AQ34: =SUM(G34:AP34) -> 12
A35: 31 | B35: Âm thanh | C35: ÂM ly 480w | D35: FV-248PA | AQ35: =SUM(G35:AP35) -> 0
A36: 32 | B36: Âm thanh | C36: Bàn trộn (Mixer) | D36: MG10XU | AG36: 1 | AQ36: =SUM(G36:AP36) -> 1
A37: 33 | B37: Âm thanh | C37: Mic đại biểu | D37: CCS-DL | AQ37: =SUM(G37:AP37) -> 0
A38: 34 | B38: Âm thanh | C38: Mic chủ tịch | D38: CCS-CML | AQ38: =SUM(G38:AP38) -> 0
A39: 35 | B39: Âm thanh | C39: Bộ điều khiển trung tâm | D39: CCS-CUD | AQ39: =SUM(G39:AP39) -> 0
A40: 36 | B40: Âm thanh | C40: cáp nối dài 10M | D40: LBB3316/10 | AQ40: =SUM(G40:AP40) -> 0
A41: 37 | B41: Âm thanh | C41: Loa hộp 30w | D41: LB2/UC30-D1 | AQ41: =SUM(G41:AP41) -> 0
A42: 38 | B42: Âm thanh | C42: Mic cài ve | D42: MW1-LTX-F5 | AG42: 10 | AQ42: =SUM(G42:AP42) -> 10
...

Sheet Tầng 5
A3: STT | B3: Phân loại | C3: Tên thiết bị | G3: Vị trí lắp đặt - Người sử dụng (Số lượng) | AL3: Tổng
D4: Mã thiết bị | E4: Cấu hình thiết bị | F4: Hãng sản xuất | G4: 5F1 | H4: 5F2 | I4: 5F3 | J4: 5F4 | K4: 5F5 | L4: 5F6 | M4: 5F7 | N4: 5F8 | O4: 5F9 | P4: 5F10 | Q4: 5F11 | R4: 5F12 | S4: 5F13 | T4: 5F14 | U4: 5F15 | V4: 5F16 | W4: 5F17 | X4: 5F18 | Y4: 5F19 | Z4: WC Y4-Y5 | AA4: WC Y15-Y16 | AB4: WC Y11-Y12 | AC4: HL Y4-Y16 | AD4: HL Y1-Y16 | AE4: Sảnh Y7-Y9 | AF4: CT bộ Y4-Y5 | AG4: HL X1-X7 | AH4: Thang bộ Y9-Y10 | AI4: Sảnh thang máy | AJ4: Thư viện | AK4: Thang bộ Y13-Y14
B5: Camera | C5: Đầu lưu trữ hình ảnh | D5: DS-7732NI-K4 | AL5: =SUM(G5:AK5) -> 0
B6: Camera | C6: Ổ cứng Seagate Skyhawk ST4000VX007 | AL6: =SUM(G6:AK6) -> 0
B7: Camera | C7: Camera IP Dome hồng ngoại 2.0 Megapixel | D7: DS-2CD1123G0E-I(L) | Q7: 1 | S7: 1 | U7: 1 | AF7: 1 | AL7: =SUM(G7:AK7) -> 4
A8: 1 | B8: Camera | C8: Camera IP dome hồng ngoại trong nhà POE (Hành lang, lớp học,thang máy…) | D8: MS-C2975-PB | AC8: 9 | AI8: 1 | AJ8: 1 | AL8: =SUM(G8:AK8) -> 11
A9: 2 | B9: Camera | C9: Camera hồng ngoại IP bullet 1080p IP66 (Sân chơi, bể bơi, sân bóng rổ, sân khấu…) | D9: MS-C2962-FPB | AL9: =SUM(G9:AK9) -> 0
A10: 3 | B10: Camera | C10: Camera bullet cho ứng dụng nhận diện khuôn mặt với P -Iris (Cổng ra vào 1,2) | D10: MS-C2862-FPB | AL10: =SUM(G10:AK10) -> 0
A11: 4 | B11: Camera | C11: Camera IP quay quét (PTZ) -quan sát toàn cảnh | D11: MS-C2941-X30R(P)B | AL11: =SUM(G11:AK11) -> 0
A12: 5 | B12: Camera | C12: Đầu lưu trữ hình ảnh | D12: MS-N8032-UH | AL12: =SUM(G12:AK12) -> 0
A13: 6 | B13: Camera | C13: Switch 08 cổng PoE + 2 SFP | D13: GS-4210-8P2S | AG13: 1 | AL13: =SUM(G13:AK13) -> 1
A14: 7 | B14: Camera | C14: Switch 24 cổng LAN trung tâm | D14: GS-5220-20T4C4X | AL14: =SUM(G14:AK14) -> 0
A15: 8 | B15: Camera | C15: Module quang | D15: MGB series MGB-LX | AG15: 1 | AL15: =SUM(G15:AK15) -> 1
A16: 9 | B16: Camera | C16: Bộ chuyển đổi quang điện | D16: GT-802S | AL16: =SUM(G16:AK16) -> 0
A17: 10 | B17: Camera | C17: Bộ chuyển đổi (Dùng cho Camera lắp trong thang máy). | D17: VC-201A-EU | AL17: =SUM(G17:AK17) -> 0
A18: 11 | B18: Camera | C18: Bộ thiết bị mạng kéo dài nguồn tích hợp công nghệ POE | D18: FPI -100GA | AL18: =SUM(G18:AK18) -> 0
A19: 12 | B19: Camera | C19: Ổ cứng Seagate Skyhawk ST4000VX007 | AL19: =SUM(G19:AK19) -> 0
A20: 13 | B20: Camera | C20: Smart Tivi Samsung 49 inch Full HD | D20: 49J5250 | AL20: =SUM(G20:AK20) -> 0
A21: 14 | B21: Camera | C21: Dây HDMI 5m | D21: Ugreen | AL21: =SUM(G21:AK21) -> 0
A22: 15 | B22: Camera | C22: Máy chủ HP | D22: 4FU52AV HP Z2 Tower G4 | AL22: =SUM(G22:AK22) -> 0
A23: 16 | B23: Camera | C23: Màn hình máy tính HP | D23: 3AL28AA HP | AL23: =SUM(G23:AK23) -> 0
A24: 17 | B24: Camera | C24: Bộ lưu điện APC Smart-UPS On-Line, 6000 Watts /6000 VA | D24: SRT6KXLI | AL24: =SUM(G24:AK24) -> 0
A25: 18 | B25: Camera | C25: Cần điều khiển chuyên dụng cho các loại Camera Bullet, Dome, PTZ ở góc view xa | D25: MS-K02 | AL25: =SUM(G25:AK25) -> 0
A26: 19 | B26: Camera | C26: Tủ trung tâm đựng thiết bị 27U -kèm SPU -Cánh cửa lưới - màu đen | D26: VN-/- | AL26: =SUM(G26:AK26) -> 0
A27: 20 | B27: Âm thanh | C27: ÂM ly 60w | D27: PLE-1MA060-EU | AL27: =SUM(G27:AK27) -> 0
A28: 21 | B28: Âm thanh | C28: ÂM ly 240w | D28: PLE-1ME240-EU | AL28: =SUM(G28:AK28) -> 0
A29: 22 | B29: Âm thanh | C29: ÂM ly 120w | D29: PLE-1MA120-EU | AL29: =SUM(G29:AK29) -> 0
A30: 23 | B30: Âm thanh | C30: Loa 6w | D30: LHM0606/10 | Z30: 2 | AA30: 2 | AB30: 2 | AD30: 9 | AE30: 1 | AL30: =SUM(G30:AK30) -> 16
A31: 24 | B31: Âm thanh | C31: Loa 24w | D31: LBC3099/41 | K31: 2 | M31: 2 | Q31: 2 | S31: 2 | U31: 2 | AL31: =SUM(G31:AK31) -> 10
A32: 25 | B32: Âm thanh | C32: Mic không dây | D32: MW1-HTX-F5 | AL32: =SUM(G32:AK32) -> 0
A33: 26 | B33: Âm thanh | C33: ÂM ly 480w | D33: LBB1938/20 | AL33: =SUM(G33:AK33) -> 0
A34: 27 | B34: Âm thanh | C34: Bộ thu | D34: MW1-RX-F5 | H34: 5 | AL34: =SUM(G34:AK34) -> 5
A35: 28 | B35: Âm thanh | C35: ÂM ly 480w | D35: FV-248PA | AL35: =SUM(G35:AK35) -> 0
A36: 29 | B36: Âm thanh | C36: Bàn trộn (Mixer) | D36: MG10XU | AL36: =SUM(G36:AK36) -> 0
A37: 30 | B37: Âm thanh | C37: Mic đại biểu | D37: CCS-DL | AL37: =SUM(G37:AK37) -> 0
A38: 31 | B38: Âm thanh | C38: Mic chủ tịch | D38: CCS-CML | AL38: =SUM(G38:AK38) -> 0
A39: 32 | B39: Âm thanh | C39: Bộ điều khiển trung tâm | D39: CCS-CUD | AL39: =SUM(G39:AK39) -> 0
A40: 33 | B40: Âm thanh | C40: cáp nối dài 10M | D40: LBB3316/10 | AL40: =SUM(G40:AK40) -> 0
A41: 34 | B41: Âm thanh | C41: Loa hộp 30w | D41: LB2/UC30-D1 | AL41: =SUM(G41:AK41) -> 0
A42: 35 | B42: Âm thanh | C42: Mic cài ve | D42: MW1-LTX-F5 | H42: 5 | AL42: =SUM(G42:AK42) -> 5
...

Sheet Tầng 6
A3: STT | B3: Phân loại | C3: Tên thiết bị | G3: Vị trí lắp đặt - Người sử dụng (Số lượng) | V3: Tổng
D4: Mã thiết bị | E4: Cấu hình thiết bị | F4: Hãng sản xuất | G4: TUM | H4: Thang máy | I4: Tủ kỹ thuật điện | J4: HÀNH LANG | K4: 6F1 | L4: 6F3 | M4: 6F5 | N4: 6F7 | O4: 6F9 | P4: 6F11 | Q4: 6F13 | R4: 6F15 | S4: 6F17 | T4: 6F19 | U4: 6F21
A5: 1 | B5: Camera | C5: Đầu lưu trữ hình ảnh | D5: DS-7732NI-K4 | V5: =SUM(G5:U5) -> 0
A6: 2 | B6: Camera | C6: Ổ cứng Seagate Skyhawk ST4000VX007 | V6: =SUM(G6:U6) -> 0
A7: 3 | B7: Camera | C7: Camera IP Dome hồng ngoại 2.0 Megapixel | D7: DS-2CD1123G0E-I(L) | J7: 3 | O7: 1 | P7: 1 | Q7: 1 | R7: 1 | S7: 1 | T7: 5 | U7: 1 | V7: =SUM(G7:U7) -> 14
A8: 4 | B8: Camera | C8: Camera IP dome hồng ngoại trong nhà POE (Hành lang, lớp học,thang máy…) | D8: MS-C2975-PB | H8: 2 | V8: =SUM(G8:U8) -> 2
A9: 5 | B9: Camera | C9: Camera hồng ngoại IP bullet 1080p IP66 (Sân chơi, bể bơi, sân bóng rổ, sân khấu…) | D9: MS-C2962-FPB | V9: =SUM(G9:U9) -> 0
A10: 6 | B10: Camera | C10: Camera bullet cho ứng dụng nhận diện khuôn mặt với P -Iris (Cổng ra vào 1,2) | D10: MS-C2862-FPB | V10: =SUM(G10:U10) -> 0
A11: 7 | B11: Camera | C11: Camera IP quay quét (PTZ) -quan sát toàn cảnh | D11: MS-C2941-X30R(P)B | G11: 3 | V11: =SUM(G11:U11) -> 3
A12: 8 | B12: Camera | C12: Đầu lưu trữ hình ảnh | D12: MS-N8032-UH | V12: =SUM(G12:U12) -> 0
A13: 9 | B13: Camera | C13: Switch 08 cổng PoE + 2 SFP | D13: GS-4210-8P2S | T13: 1 | V13: =SUM(G13:U13) -> 1
A14: 10 | B14: Camera | C14: Switch 24 cổng LAN trung tâm | D14: GS-5220-20T4C4X | V14: =SUM(G14:U14) -> 0
A15: 11 | B15: Camera | C15: Module quang | D15: MGB series MGB-LX | V15: =SUM(G15:U15) -> 0
A16: 12 | B16: Camera | C16: Bộ chuyển đổi quang điện | D16: GT-802S | H16: 2 | V16: =SUM(G16:U16) -> 2
A17: 13 | B17: Camera | C17: Bộ chuyển đổi (Dùng cho Camera lắp trong thang máy). | D17: VC-201A-EU | H17: 4 | V17: =SUM(G17:U17) -> 4
A18: 14 | B18: Camera | C18: Bộ thiết bị mạng kéo dài nguồn tích hợp công nghệ POE | D18: FPI -100GA | H18: 2 | V18: =SUM(G18:U18) -> 2
A19: 15 | B19: Camera | C19: Ổ cứng Seagate Skyhawk ST4000VX007 | V19: =SUM(G19:U19) -> 0
A20: 16 | B20: Camera | C20: Smart Tivi Samsung 49 inch Full HD | D20: 49J5250 | V20: =SUM(G20:U20) -> 0
A21: 17 | B21: Camera | C21: Dây HDMI 5m | D21: Ugreen | V21: =SUM(G21:U21) -> 0
A22: 18 | B22: Camera | C22: Máy chủ HP | D22: 4FU52AV HP Z2 Tower G4 | V22: =SUM(G22:U22) -> 0
A23: 19 | B23: Camera | C23: Màn hình máy tính HP | D23: 3AL28AA HP | V23: =SUM(G23:U23) -> 0
A24: 20 | B24: Camera | C24: Bộ lưu điện APC Smart-UPS On-Line, 6000 Watts /6000 VA | D24: SRT6KXLI | V24: =SUM(G24:U24) -> 0
A25: 21 | B25: Camera | C25: Cần điều khiển chuyên dụng cho các loại Camera Bullet, Dome, PTZ ở góc view xa | D25: MS-K02 | V25: =SUM(G25:U25) -> 0
A26: 22 | B26: Camera | C26: Tủ trung tâm đựng thiết bị 27U -kèm SPU -Cánh cửa lưới - màu đen | D26: VN-/- | V26: =SUM(G26:U26) -> 0
A27: 23 | B27: Âm thanh | C27: ÂM ly 60w | D27: PLE-1MA060-EU | O27: 1 | P27: 1 | Q27: 1 | U27: 1 | V27: =SUM(G27:U27) -> 4
A28: 24 | B28: Âm thanh | C28: ÂM ly 240w | D28: PLE-1ME240-EU | I28: 1 | V28: =SUM(G28:U28) -> 1
A29: 25 | B29: Âm thanh | C29: ÂM ly 120w | D29: PLE-1MA120-EU | V29: =SUM(G29:U29) -> 0
A30: 26 | B30: Âm thanh | C30: Loa 6w | D30: LHM0606/10 | V30: =SUM(G30:U30) -> 0
A31: 27 | B31: Âm thanh | C31: Loa 24w | D31: LBC3099/41 | O31: 2 | P31: 2 | Q31: 2 | U31: 4 | V31: =SUM(G31:U31) -> 10
A32: 28 | B32: Âm thanh | C32: Mic không dây | D32: MW1-HTX-F5 | U32: 1 | V32: =SUM(G32:U32) -> 1
A33: 29 | B33: Âm thanh | C33: ÂM ly 480w | D33: LBB1938/20 | V33: =SUM(G33:U33) -> 0
A34: 30 | B34: Âm thanh | C34: Bộ thu | D34: MW1-RX-F5 | U34: 1 | V34: =SUM(G34:U34) -> 1
A35: 31 | B35: Âm thanh | C35: ÂM ly 480w | D35: FV-248PA | V35: =SUM(G35:U35) -> 0
A36: 32 | B36: Âm thanh | C36: Bàn trộn (Mixer) | D36: MG10XU | V36: =SUM(G36:U36) -> 0
A37: 33 | B37: Âm thanh | C37: Mic đại biểu | D37: CCS-DL | V37: =SUM(G37:U37) -> 0
A38: 34 | B38: Âm thanh | C38: Mic chủ tịch | D38: CCS-CML | V38: =SUM(G38:U38) -> 0
A39: 35 | B39: Âm thanh | C39: Bộ điều khiển trung tâm | D39: CCS-CUD | V39: =SUM(G39:U39) -> 0
A40: 36 | B40: Âm thanh | C40: cáp nối dài 10M | D40: LBB3316/10 | V40: =SUM(G40:U40) -> 0
A41: 37 | B41: Âm thanh | C41: Loa hộp 30w | D41: LB2/UC30-D1 | V41: =SUM(G41:U41) -> 0
A42: 38 | B42: Âm thanh | C42: Mic cài ve | D42: MW1-LTX-F5 | V42: =SUM(G42:U42) -> 0
...
